<?xml version="1.0" encoding="UTF-8" ?>
<robot name="arm">

  <!-- ================= base_link ================= -->
  <link name="base_link">
    <visual>
      <origin xyz="0 0 0" rpy="0 0 0"/>
      <geometry>
        <mesh filename="meshes/base_link.STL"/>
      </geometry>
    </visual>
    <collision>
      <origin xyz="0 0 0" rpy="0 0 0"/>
      <geometry>
        <mesh filename="meshes/base_link.STL"/>
      </geometry>
    </collision>
  </link>

  <!-- ================= link1 ================= -->
  <link name="link1">
    <visual>
      <origin xyz="0 0 0" rpy="0 0 0"/>
      <geometry>
        <mesh filename="meshes/link1.STL"/>
      </geometry>
    </visual>
    <collision>
      <origin xyz="0 0 0" rpy="0 0 0"/>
      <geometry>
        <mesh filename="meshes/link1.STL"/>
      </geometry>
    </collision>
  </link>

  <joint name="joint1" type="revolute">
    <origin xyz="0 0 0.06605" rpy="-0.010805 0 0"/>
    <parent link="base_link"/>
    <child link="link1"/>
    <axis xyz="0 0 1"/>
    <limit effort="30" velocity="1.0" lower="-1.5708" upper="1.5708"/>
  </joint>

  <!-- ================= link2 ================= -->
  <link name="link2">
    <visual>
      <origin xyz="0 0 0" rpy="0 0 0"/>
      <geometry>
        <mesh filename="meshes/link2.STL"/>
      </geometry>
    </visual>
    <collision>
      <origin xyz="0 0 0" rpy="0 0 0"/>
      <geometry>
        <mesh filename="meshes/link2.STL"/>
      </geometry>
    </collision>
  </link>

  <joint name="joint2" type="revolute">
    <origin xyz="0 -0.00031873 0.04145" rpy="0 1.5708 0"/>
    <parent link="link1"/>
    <child link="link2"/>
    <axis xyz="0 0 1"/>
    <limit effort="30" velocity="1.0" lower="-1.5708" upper="1.5708"/>
  </joint>

  <!-- ================= link3 ================= -->
  <link name="link3">
    <visual>
      <origin xyz="0 0 0" rpy="0 0 0"/>
      <geometry>
        <mesh filename="meshes/link3.STL"/>
      </geometry>
    </visual>
    <collision>
      <origin xyz="0 0 0" rpy="0 0 0"/>
      <geometry>
        <mesh filename="meshes/link3.STL"/>
      </geometry>
    </collision>
  </link>

  <joint name="joint3" type="revolute">
    <origin xyz="-0.08285 0 0" rpy="0 0 0"/>
    <parent link="link2"/>
    <child link="link3"/>
    <axis xyz="0 0 1"/>
    <limit effort="30" velocity="1.0" lower="-1.5708" upper="1.5708"/>
  </joint>

  <!-- ================= link4 ================= -->
  <link name="link4">
    <visual>
      <origin xyz="0 0 0" rpy="0 0 0"/>
      <geometry>
        <mesh filename="meshes/link4.STL"/>
      </geometry>
    </visual>
    <collision>
      <origin xyz="0 0 0" rpy="0 0 0"/>
      <geometry>
        <mesh filename="meshes/link4.STL"/>
      </geometry>
    </collision>
  </link>

  <joint name="joint4" type="revolute">
    <origin xyz="-0.08285 0 0" rpy="0 0 0.0083081"/>
    <parent link="link3"/>
    <child link="link4"/>
    <axis xyz="0 0 1"/>
    <limit effort="30" velocity="1.0" lower="-1.5708" upper="1.5708"/>
  </joint>

  <!-- ================= link5 ================= -->
  <link name="link5">
    <visual>
      <origin xyz="0 0 0" rpy="0 0 0"/>
      <geometry>
        <mesh filename="meshes/link5.STL"/>
      </geometry>
    </visual>
    <collision>
      <origin xyz="0 0 0" rpy="0 0 0"/>
      <geometry>
        <mesh filename="meshes/link5.STL"/>
      </geometry>
    </collision>
  </link>

  <joint name="joint5" type="revolute">
    <origin xyz="-0.07385 -0.001 0" rpy="0 -1.57 0"/>
    <parent link="link4"/>
    <child link="link5"/>
    <axis xyz="0 0 1"/>
    <limit effort="30" velocity="1.0" lower="-1.5708" upper="3.1416"/>
  </joint>

</robot>
